Exceptions: ('unexpected alert open: {Alert text : 상품평을 불러오던 중에 오류가 발생했습니다.}\n  (Session info: headless chrome=64.0.3282.167)\n  (Driver info: chromedriver=2.34.522940 (1a76f96f66e3ca7b8e57d503b4dd3bccfba87af1),platform=Windows NT 6.3.9600 x86_64)', None, None) traceback : Traceback (most recent call last):
  File "C:\Users\admin\IdeaProjects\py-myweb_crawler\crawler.py", line 343, in mining
    data_list = self.parser.parse_to_list(self.driver)
  File "C:\Users\admin\IdeaProjects\py-myweb_crawler\crawler.py", line 146, in parse_to_list
    root.get(url)
  File "C:\Users\admin\AppData\Local\Programs\Python\Python35\lib\site-packages\selenium\webdriver\remote\webdriver.py", line 324, in get
    self.execute(Command.GET, {'url': url})
  File "C:\Users\admin\AppData\Local\Programs\Python\Python35\lib\site-packages\selenium\webdriver\remote\webdriver.py", line 312, in execute
    self.error_handler.check_response(response)
  File "C:\Users\admin\AppData\Local\Programs\Python\Python35\lib\site-packages\selenium\webdriver\remote\errorhandler.py", line 237, in check_response
    raise exception_class(message, screen, stacktrace)
selenium.common.exceptions.UnexpectedAlertPresentException: Alert Text: None
Message: unexpected alert open: {Alert text : 상품평을 불러오던 중에 오류가 발생했습니다.}
  (Session info: headless chrome=64.0.3282.167)
  (Driver info: chromedriver=2.34.522940 (1a76f96f66e3ca7b8e57d503b4dd3bccfba87af1),platform=Windows NT 6.3.9600 x86_64)


(2018-02-27 15:34:45)
Exceptions: ('unexpected alert open: {Alert text : 상품평을 불러오던 중에 오류가 발생했습니다.}\n  (Session info: headless chrome=64.0.3282.167)\n  (Driver info: chromedriver=2.34.522940 (1a76f96f66e3ca7b8e57d503b4dd3bccfba87af1),platform=Windows NT 6.3.9600 x86_64)', None, None) traceback : Traceback (most recent call last):
  File "C:\Users\admin\IdeaProjects\py-myweb_crawler\crawler.py", line 343, in mining
    data_list = self.parser.parse_to_list(self.driver)
  File "C:\Users\admin\IdeaProjects\py-myweb_crawler\crawler.py", line 146, in parse_to_list
    root.get(url)
  File "C:\Users\admin\AppData\Local\Programs\Python\Python35\lib\site-packages\selenium\webdriver\remote\webdriver.py", line 324, in get
    self.execute(Command.GET, {'url': url})
  File "C:\Users\admin\AppData\Local\Programs\Python\Python35\lib\site-packages\selenium\webdriver\remote\webdriver.py", line 312, in execute
    self.error_handler.check_response(response)
  File "C:\Users\admin\AppData\Local\Programs\Python\Python35\lib\site-packages\selenium\webdriver\remote\errorhandler.py", line 237, in check_response
    raise exception_class(message, screen, stacktrace)
selenium.common.exceptions.UnexpectedAlertPresentException: Alert Text: None
Message: unexpected alert open: {Alert text : 상품평을 불러오던 중에 오류가 발생했습니다.}
  (Session info: headless chrome=64.0.3282.167)
  (Driver info: chromedriver=2.34.522940 (1a76f96f66e3ca7b8e57d503b4dd3bccfba87af1),platform=Windows NT 6.3.9600 x86_64)


(2018-02-27 20:43:03)
Exceptions: ('unexpected alert open: {Alert text : 상품평을 불러오던 중에 오류가 발생했습니다.}\n  (Session info: headless chrome=64.0.3282.167)\n  (Driver info: chromedriver=2.34.522940 (1a76f96f66e3ca7b8e57d503b4dd3bccfba87af1),platform=Windows NT 6.3.9600 x86_64)', None, None) traceback : Traceback (most recent call last):
  File "C:\Users\admin\IdeaProjects\py-myweb_crawler\crawler.py", line 343, in mining
    data_list = self.parser.parse_to_list(self.driver)
  File "C:\Users\admin\IdeaProjects\py-myweb_crawler\crawler.py", line 146, in parse_to_list
    root.get(url)
  File "C:\Users\admin\AppData\Local\Programs\Python\Python35\lib\site-packages\selenium\webdriver\remote\webdriver.py", line 324, in get
    self.execute(Command.GET, {'url': url})
  File "C:\Users\admin\AppData\Local\Programs\Python\Python35\lib\site-packages\selenium\webdriver\remote\webdriver.py", line 312, in execute
    self.error_handler.check_response(response)
  File "C:\Users\admin\AppData\Local\Programs\Python\Python35\lib\site-packages\selenium\webdriver\remote\errorhandler.py", line 237, in check_response
    raise exception_class(message, screen, stacktrace)
selenium.common.exceptions.UnexpectedAlertPresentException: Alert Text: None
Message: unexpected alert open: {Alert text : 상품평을 불러오던 중에 오류가 발생했습니다.}
  (Session info: headless chrome=64.0.3282.167)
  (Driver info: chromedriver=2.34.522940 (1a76f96f66e3ca7b8e57d503b4dd3bccfba87af1),platform=Windows NT 6.3.9600 x86_64)


(2018-02-27 20:43:06)
Exceptions: ('unexpected alert open: {Alert text : 상품평을 불러오던 중에 오류가 발생했습니다.}\n  (Session info: headless chrome=64.0.3282.167)\n  (Driver info: chromedriver=2.34.522940 (1a76f96f66e3ca7b8e57d503b4dd3bccfba87af1),platform=Windows NT 6.3.9600 x86_64)', None, None) traceback : Traceback (most recent call last):
  File "C:\Users\admin\IdeaProjects\py-myweb_crawler\crawler.py", line 343, in mining
    data_list = self.parser.parse_to_list(self.driver)
  File "C:\Users\admin\IdeaProjects\py-myweb_crawler\crawler.py", line 146, in parse_to_list
    root.get(url)
  File "C:\Users\admin\AppData\Local\Programs\Python\Python35\lib\site-packages\selenium\webdriver\remote\webdriver.py", line 324, in get
    self.execute(Command.GET, {'url': url})
  File "C:\Users\admin\AppData\Local\Programs\Python\Python35\lib\site-packages\selenium\webdriver\remote\webdriver.py", line 312, in execute
    self.error_handler.check_response(response)
  File "C:\Users\admin\AppData\Local\Programs\Python\Python35\lib\site-packages\selenium\webdriver\remote\errorhandler.py", line 237, in check_response
    raise exception_class(message, screen, stacktrace)
selenium.common.exceptions.UnexpectedAlertPresentException: Alert Text: None
Message: unexpected alert open: {Alert text : 상품평을 불러오던 중에 오류가 발생했습니다.}
  (Session info: headless chrome=64.0.3282.167)
  (Driver info: chromedriver=2.34.522940 (1a76f96f66e3ca7b8e57d503b4dd3bccfba87af1),platform=Windows NT 6.3.9600 x86_64)


(2018-02-27 21:15:40)
Exceptions: ('unexpected alert open: {Alert text : 상품평을 불러오던 중에 오류가 발생했습니다.}\n  (Session info: headless chrome=64.0.3282.167)\n  (Driver info: chromedriver=2.34.522940 (1a76f96f66e3ca7b8e57d503b4dd3bccfba87af1),platform=Windows NT 6.3.9600 x86_64)', None, None) traceback : Traceback (most recent call last):
  File "C:\Users\admin\IdeaProjects\py-myweb_crawler\crawler.py", line 343, in mining
    data_list = self.parser.parse_to_list(self.driver)
  File "C:\Users\admin\IdeaProjects\py-myweb_crawler\crawler.py", line 146, in parse_to_list
    root.get(url)
  File "C:\Users\admin\AppData\Local\Programs\Python\Python35\lib\site-packages\selenium\webdriver\remote\webdriver.py", line 324, in get
    self.execute(Command.GET, {'url': url})
  File "C:\Users\admin\AppData\Local\Programs\Python\Python35\lib\site-packages\selenium\webdriver\remote\webdriver.py", line 312, in execute
    self.error_handler.check_response(response)
  File "C:\Users\admin\AppData\Local\Programs\Python\Python35\lib\site-packages\selenium\webdriver\remote\errorhandler.py", line 237, in check_response
    raise exception_class(message, screen, stacktrace)
selenium.common.exceptions.UnexpectedAlertPresentException: Alert Text: None
Message: unexpected alert open: {Alert text : 상품평을 불러오던 중에 오류가 발생했습니다.}
  (Session info: headless chrome=64.0.3282.167)
  (Driver info: chromedriver=2.34.522940 (1a76f96f66e3ca7b8e57d503b4dd3bccfba87af1),platform=Windows NT 6.3.9600 x86_64)


(2018-02-27 21:15:42)
Exceptions: ('unexpected alert open: {Alert text : 상품평을 불러오던 중에 오류가 발생했습니다.}\n  (Session info: headless chrome=64.0.3282.167)\n  (Driver info: chromedriver=2.34.522940 (1a76f96f66e3ca7b8e57d503b4dd3bccfba87af1),platform=Windows NT 6.3.9600 x86_64)', None, None) traceback : Traceback (most recent call last):
  File "C:\Users\admin\IdeaProjects\py-myweb_crawler\crawler.py", line 343, in mining
    data_list = self.parser.parse_to_list(self.driver)
  File "C:\Users\admin\IdeaProjects\py-myweb_crawler\crawler.py", line 146, in parse_to_list
    root.get(url)
  File "C:\Users\admin\AppData\Local\Programs\Python\Python35\lib\site-packages\selenium\webdriver\remote\webdriver.py", line 324, in get
    self.execute(Command.GET, {'url': url})
  File "C:\Users\admin\AppData\Local\Programs\Python\Python35\lib\site-packages\selenium\webdriver\remote\webdriver.py", line 312, in execute
    self.error_handler.check_response(response)
  File "C:\Users\admin\AppData\Local\Programs\Python\Python35\lib\site-packages\selenium\webdriver\remote\errorhandler.py", line 237, in check_response
    raise exception_class(message, screen, stacktrace)
selenium.common.exceptions.UnexpectedAlertPresentException: Alert Text: None
Message: unexpected alert open: {Alert text : 상품평을 불러오던 중에 오류가 발생했습니다.}
  (Session info: headless chrome=64.0.3282.167)
  (Driver info: chromedriver=2.34.522940 (1a76f96f66e3ca7b8e57d503b4dd3bccfba87af1),platform=Windows NT 6.3.9600 x86_64)


(2018-02-27 21:23:53)
Exceptions: ('unexpected alert open: {Alert text : 상품평을 불러오던 중에 오류가 발생했습니다.}\n  (Session info: headless chrome=64.0.3282.167)\n  (Driver info: chromedriver=2.34.522940 (1a76f96f66e3ca7b8e57d503b4dd3bccfba87af1),platform=Windows NT 6.3.9600 x86_64)', None, None) traceback : Traceback (most recent call last):
  File "C:\Users\admin\IdeaProjects\py-myweb_crawler\crawler.py", line 343, in mining
    data_list = self.parser.parse_to_list(self.driver)
  File "C:\Users\admin\IdeaProjects\py-myweb_crawler\crawler.py", line 146, in parse_to_list
    root.get(url)
  File "C:\Users\admin\AppData\Local\Programs\Python\Python35\lib\site-packages\selenium\webdriver\remote\webdriver.py", line 324, in get
    self.execute(Command.GET, {'url': url})
  File "C:\Users\admin\AppData\Local\Programs\Python\Python35\lib\site-packages\selenium\webdriver\remote\webdriver.py", line 312, in execute
    self.error_handler.check_response(response)
  File "C:\Users\admin\AppData\Local\Programs\Python\Python35\lib\site-packages\selenium\webdriver\remote\errorhandler.py", line 237, in check_response
    raise exception_class(message, screen, stacktrace)
selenium.common.exceptions.UnexpectedAlertPresentException: Alert Text: None
Message: unexpected alert open: {Alert text : 상품평을 불러오던 중에 오류가 발생했습니다.}
  (Session info: headless chrome=64.0.3282.167)
  (Driver info: chromedriver=2.34.522940 (1a76f96f66e3ca7b8e57d503b4dd3bccfba87af1),platform=Windows NT 6.3.9600 x86_64)


(2018-02-27 21:23:54)
Exceptions: ('unexpected alert open: {Alert text : 상품평을 불러오던 중에 오류가 발생했습니다.}\n  (Session info: headless chrome=64.0.3282.167)\n  (Driver info: chromedriver=2.34.522940 (1a76f96f66e3ca7b8e57d503b4dd3bccfba87af1),platform=Windows NT 6.3.9600 x86_64)', None, None) traceback : Traceback (most recent call last):
  File "C:\Users\admin\IdeaProjects\py-myweb_crawler\crawler.py", line 343, in mining
    data_list = self.parser.parse_to_list(self.driver)
  File "C:\Users\admin\IdeaProjects\py-myweb_crawler\crawler.py", line 146, in parse_to_list
    root.get(url)
  File "C:\Users\admin\AppData\Local\Programs\Python\Python35\lib\site-packages\selenium\webdriver\remote\webdriver.py", line 324, in get
    self.execute(Command.GET, {'url': url})
  File "C:\Users\admin\AppData\Local\Programs\Python\Python35\lib\site-packages\selenium\webdriver\remote\webdriver.py", line 312, in execute
    self.error_handler.check_response(response)
  File "C:\Users\admin\AppData\Local\Programs\Python\Python35\lib\site-packages\selenium\webdriver\remote\errorhandler.py", line 237, in check_response
    raise exception_class(message, screen, stacktrace)
selenium.common.exceptions.UnexpectedAlertPresentException: Alert Text: None
Message: unexpected alert open: {Alert text : 상품평을 불러오던 중에 오류가 발생했습니다.}
  (Session info: headless chrome=64.0.3282.167)
  (Driver info: chromedriver=2.34.522940 (1a76f96f66e3ca7b8e57d503b4dd3bccfba87af1),platform=Windows NT 6.3.9600 x86_64)


(2018-02-27 21:25:06)
Exceptions: ('unexpected alert open: {Alert text : 상품평을 불러오던 중에 오류가 발생했습니다.}\n  (Session info: headless chrome=64.0.3282.167)\n  (Driver info: chromedriver=2.34.522940 (1a76f96f66e3ca7b8e57d503b4dd3bccfba87af1),platform=Windows NT 6.3.9600 x86_64)', None, None) traceback : Traceback (most recent call last):
  File "C:\Users\admin\IdeaProjects\py-myweb_crawler\crawler.py", line 343, in mining
    data_list = self.parser.parse_to_list(self.driver)
  File "C:\Users\admin\IdeaProjects\py-myweb_crawler\crawler.py", line 146, in parse_to_list
    root.get(url)
  File "C:\Users\admin\AppData\Local\Programs\Python\Python35\lib\site-packages\selenium\webdriver\remote\webdriver.py", line 324, in get
    self.execute(Command.GET, {'url': url})
  File "C:\Users\admin\AppData\Local\Programs\Python\Python35\lib\site-packages\selenium\webdriver\remote\webdriver.py", line 312, in execute
    self.error_handler.check_response(response)
  File "C:\Users\admin\AppData\Local\Programs\Python\Python35\lib\site-packages\selenium\webdriver\remote\errorhandler.py", line 237, in check_response
    raise exception_class(message, screen, stacktrace)
selenium.common.exceptions.UnexpectedAlertPresentException: Alert Text: None
Message: unexpected alert open: {Alert text : 상품평을 불러오던 중에 오류가 발생했습니다.}
  (Session info: headless chrome=64.0.3282.167)
  (Driver info: chromedriver=2.34.522940 (1a76f96f66e3ca7b8e57d503b4dd3bccfba87af1),platform=Windows NT 6.3.9600 x86_64)


(2018-02-27 21:25:08)
