Exceptions: ('no such element: Unable to locate element: {"method":"xpath","selector":"a/*[@class="search-product-wrap"]/*[@class="descriptions"]/*[@class="descriptions-inner"]/*[@class="price-area"]/*[@class="price-wrap"]/*[@class="price"]/*[@class="price-info"]/*[@class="base-price"]"}\n  (Session info: headless chrome=65.0.3325.162)\n  (Driver info: chromedriver=2.36.540470 (e522d04694c7ebea4ba8821272dbef4f9b818c91),platform=Windows NT 6.3.9600 x86_64)', None, None) traceback : Traceback (most recent call last):
  File "C:/Users/admin/IdeaProjects/py-myweb_crawler/crawler.py", line 195, in parse_to_list
    price0 = Repeater.repeat_function(article.find_element_by_xpath,{self.parser_unit.price},StaleElementReferenceException,2)
  File "C:\Users\admin\IdeaProjects\py-myweb_crawler\repeater.py", line 24, in repeat_function
    return func(*params)
  File "C:\Users\admin\AppData\Local\Programs\Python\Python35\lib\site-packages\selenium\webdriver\remote\webelement.py", line 351, in find_element_by_xpath
    return self.find_element(by=By.XPATH, value=xpath)
  File "C:\Users\admin\AppData\Local\Programs\Python\Python35\lib\site-packages\selenium\webdriver\remote\webelement.py", line 645, in find_element
    {"using": by, "value": value})['value']
  File "C:\Users\admin\AppData\Local\Programs\Python\Python35\lib\site-packages\selenium\webdriver\remote\webelement.py", line 628, in _execute
    return self._parent.execute(command, params)
  File "C:\Users\admin\AppData\Local\Programs\Python\Python35\lib\site-packages\selenium\webdriver\remote\webdriver.py", line 312, in execute
    self.error_handler.check_response(response)
  File "C:\Users\admin\AppData\Local\Programs\Python\Python35\lib\site-packages\selenium\webdriver\remote\errorhandler.py", line 237, in check_response
    raise exception_class(message, screen, stacktrace)
selenium.common.exceptions.NoSuchElementException: Message: no such element: Unable to locate element: {"method":"xpath","selector":"a/*[@class="search-product-wrap"]/*[@class="descriptions"]/*[@class="descriptions-inner"]/*[@class="price-area"]/*[@class="price-wrap"]/*[@class="price"]/*[@class="price-info"]/*[@class="base-price"]"}
  (Session info: headless chrome=65.0.3325.162)
  (Driver info: chromedriver=2.36.540470 (e522d04694c7ebea4ba8821272dbef4f9b818c91),platform=Windows NT 6.3.9600 x86_64)


(2018-03-20 00:44:16)
===============================================

Exceptions: ('no such element: Unable to locate element: {"method":"xpath","selector":"a/*[@class="search-product-wrap"]/*[@class="descriptions"]/*[@class="descriptions-inner"]/*[@class="price-area"]/*[@class="price-wrap"]/*[@class="price"]/*[@class="sale"]/strong"}\n  (Session info: headless chrome=65.0.3325.162)\n  (Driver info: chromedriver=2.36.540470 (e522d04694c7ebea4ba8821272dbef4f9b818c91),platform=Windows NT 6.3.9600 x86_64)', None, None) traceback : Traceback (most recent call last):
  File "C:/Users/admin/IdeaProjects/py-myweb_crawler/crawler.py", line 195, in parse_to_list
    price0 = Repeater.repeat_function(article.find_element_by_xpath,{self.parser_unit.price},StaleElementReferenceException,2)
  File "C:\Users\admin\IdeaProjects\py-myweb_crawler\repeater.py", line 24, in repeat_function
    return func(*params)
  File "C:\Users\admin\AppData\Local\Programs\Python\Python35\lib\site-packages\selenium\webdriver\remote\webelement.py", line 351, in find_element_by_xpath
    return self.find_element(by=By.XPATH, value=xpath)
  File "C:\Users\admin\AppData\Local\Programs\Python\Python35\lib\site-packages\selenium\webdriver\remote\webelement.py", line 645, in find_element
    {"using": by, "value": value})['value']
  File "C:\Users\admin\AppData\Local\Programs\Python\Python35\lib\site-packages\selenium\webdriver\remote\webelement.py", line 628, in _execute
    return self._parent.execute(command, params)
  File "C:\Users\admin\AppData\Local\Programs\Python\Python35\lib\site-packages\selenium\webdriver\remote\webdriver.py", line 312, in execute
    self.error_handler.check_response(response)
  File "C:\Users\admin\AppData\Local\Programs\Python\Python35\lib\site-packages\selenium\webdriver\remote\errorhandler.py", line 237, in check_response
    raise exception_class(message, screen, stacktrace)
selenium.common.exceptions.NoSuchElementException: Message: no such element: Unable to locate element: {"method":"xpath","selector":"a/*[@class="search-product-wrap"]/*[@class="descriptions"]/*[@class="descriptions-inner"]/*[@class="price-area"]/*[@class="price-wrap"]/*[@class="price"]/*[@class="sale"]/strong"}
  (Session info: headless chrome=65.0.3325.162)
  (Driver info: chromedriver=2.36.540470 (e522d04694c7ebea4ba8821272dbef4f9b818c91),platform=Windows NT 6.3.9600 x86_64)


(2018-03-20 00:49:10)
===============================================

Exceptions: () traceback : Traceback (most recent call last):
  File "C:/Users/admin/IdeaProjects/py-myweb_crawler/crawler.py", line 292, in out_from_xpath
    return root.find_elements_by_xpath(xpath)
  File "C:\Users\admin\AppData\Local\Programs\Python\Python35\lib\site-packages\selenium\webdriver\remote\webdriver.py", line 401, in find_elements_by_xpath
    return self.find_elements(by=By.XPATH, value=xpath)
  File "C:\Users\admin\AppData\Local\Programs\Python\Python35\lib\site-packages\selenium\webdriver\remote\webdriver.py", line 983, in find_elements
    'value': value})['value'] or []
  File "C:\Users\admin\AppData\Local\Programs\Python\Python35\lib\site-packages\selenium\webdriver\remote\webdriver.py", line 312, in execute
    self.error_handler.check_response(response)
  File "C:\Users\admin\AppData\Local\Programs\Python\Python35\lib\site-packages\selenium\webdriver\remote\errorhandler.py", line 237, in check_response
    raise exception_class(message, screen, stacktrace)
selenium.common.exceptions.UnexpectedAlertPresentException: Alert Text: None
Message: unexpected alert open: {Alert text : 서비스 접속이 원할하지 않습니다.
잠시 후에 다시 방문하여 주시기 바랍니다.}
  (Session info: headless chrome=65.0.3325.162)
  (Driver info: chromedriver=2.36.540470 (e522d04694c7ebea4ba8821272dbef4f9b818c91),platform=Windows NT 6.3.9600 x86_64)


During handling of the above exception, another exception occurred:

Traceback (most recent call last):
  File "C:/Users/admin/IdeaProjects/py-myweb_crawler/crawler.py", line 255, in find_category_info
    loaded_categories = ParserImpl.out_from_xpath(driver, categories)
  File "C:/Users/admin/IdeaProjects/py-myweb_crawler/crawler.py", line 297, in out_from_xpath
    raise NoSuchElementException
selenium.common.exceptions.NoSuchElementException: Message: None


During handling of the above exception, another exception occurred:

Traceback (most recent call last):
  File "C:/Users/admin/IdeaProjects/py-myweb_crawler/crawler.py", line 203, in parse_to_list
    root, self.parser_unit.categories, self.parser_unit.category_core
  File "C:/Users/admin/IdeaProjects/py-myweb_crawler/crawler.py", line 279, in find_category_info
    raise NoSuchElementException
selenium.common.exceptions.NoSuchElementException: Message: None


(2018-03-20 00:55:09)
===============================================

Exceptions: ('no such element: Unable to locate element: {"method":"xpath","selector":"//*[@id="productList"]"}\n  (Session info: headless chrome=65.0.3325.162)\n  (Driver info: chromedriver=2.36.540470 (e522d04694c7ebea4ba8821272dbef4f9b818c91),platform=Windows NT 6.3.9600 x86_64)', None, None) traceback : Traceback (most recent call last):
  File "C:/Users/admin/IdeaProjects/py-myweb_crawler/crawler.py", line 185, in parse_to_list
    section = driver.find_element_by_xpath(self.parser_unit.section)
  File "C:\Users\admin\AppData\Local\Programs\Python\Python35\lib\site-packages\selenium\webdriver\remote\webdriver.py", line 385, in find_element_by_xpath
    return self.find_element(by=By.XPATH, value=xpath)
  File "C:\Users\admin\AppData\Local\Programs\Python\Python35\lib\site-packages\selenium\webdriver\remote\webdriver.py", line 955, in find_element
    'value': value})['value']
  File "C:\Users\admin\AppData\Local\Programs\Python\Python35\lib\site-packages\selenium\webdriver\remote\webdriver.py", line 312, in execute
    self.error_handler.check_response(response)
  File "C:\Users\admin\AppData\Local\Programs\Python\Python35\lib\site-packages\selenium\webdriver\remote\errorhandler.py", line 237, in check_response
    raise exception_class(message, screen, stacktrace)
selenium.common.exceptions.NoSuchElementException: Message: no such element: Unable to locate element: {"method":"xpath","selector":"//*[@id="productList"]"}
  (Session info: headless chrome=65.0.3325.162)
  (Driver info: chromedriver=2.36.540470 (e522d04694c7ebea4ba8821272dbef4f9b818c91),platform=Windows NT 6.3.9600 x86_64)


(2018-03-20 00:55:11)
===============================================

Exceptions: () traceback : Traceback (most recent call last):
  File "C:/Users/admin/IdeaProjects/py-myweb_crawler/crawler.py", line 292, in out_from_xpath
    return root.find_elements_by_xpath(xpath)
  File "C:\Users\admin\AppData\Local\Programs\Python\Python35\lib\site-packages\selenium\webdriver\remote\webdriver.py", line 401, in find_elements_by_xpath
    return self.find_elements(by=By.XPATH, value=xpath)
  File "C:\Users\admin\AppData\Local\Programs\Python\Python35\lib\site-packages\selenium\webdriver\remote\webdriver.py", line 983, in find_elements
    'value': value})['value'] or []
  File "C:\Users\admin\AppData\Local\Programs\Python\Python35\lib\site-packages\selenium\webdriver\remote\webdriver.py", line 312, in execute
    self.error_handler.check_response(response)
  File "C:\Users\admin\AppData\Local\Programs\Python\Python35\lib\site-packages\selenium\webdriver\remote\errorhandler.py", line 237, in check_response
    raise exception_class(message, screen, stacktrace)
selenium.common.exceptions.UnexpectedAlertPresentException: Alert Text: None
Message: unexpected alert open: {Alert text : 데이터 처리에 실패했습니다. 다시 시도해 주세요.}
  (Session info: headless chrome=65.0.3325.162)
  (Driver info: chromedriver=2.36.540470 (e522d04694c7ebea4ba8821272dbef4f9b818c91),platform=Windows NT 6.3.9600 x86_64)


During handling of the above exception, another exception occurred:

Traceback (most recent call last):
  File "C:/Users/admin/IdeaProjects/py-myweb_crawler/crawler.py", line 255, in find_category_info
    loaded_categories = ParserImpl.out_from_xpath(driver, categories)
  File "C:/Users/admin/IdeaProjects/py-myweb_crawler/crawler.py", line 297, in out_from_xpath
    raise NoSuchElementException
selenium.common.exceptions.NoSuchElementException: Message: None


During handling of the above exception, another exception occurred:

Traceback (most recent call last):
  File "C:/Users/admin/IdeaProjects/py-myweb_crawler/crawler.py", line 203, in parse_to_list
    root, self.parser_unit.categories, self.parser_unit.category_core
  File "C:/Users/admin/IdeaProjects/py-myweb_crawler/crawler.py", line 279, in find_category_info
    raise NoSuchElementException
selenium.common.exceptions.NoSuchElementException: Message: None


(2018-03-20 01:00:29)
===============================================

Exceptions: ('no such element: Unable to locate element: {"method":"xpath","selector":"//*[@id="productList"]"}\n  (Session info: headless chrome=65.0.3325.162)\n  (Driver info: chromedriver=2.36.540470 (e522d04694c7ebea4ba8821272dbef4f9b818c91),platform=Windows NT 6.3.9600 x86_64)', None, None) traceback : Traceback (most recent call last):
  File "C:/Users/admin/IdeaProjects/py-myweb_crawler/crawler.py", line 185, in parse_to_list
    section = driver.find_element_by_xpath(self.parser_unit.section)
  File "C:\Users\admin\AppData\Local\Programs\Python\Python35\lib\site-packages\selenium\webdriver\remote\webdriver.py", line 385, in find_element_by_xpath
    return self.find_element(by=By.XPATH, value=xpath)
  File "C:\Users\admin\AppData\Local\Programs\Python\Python35\lib\site-packages\selenium\webdriver\remote\webdriver.py", line 955, in find_element
    'value': value})['value']
  File "C:\Users\admin\AppData\Local\Programs\Python\Python35\lib\site-packages\selenium\webdriver\remote\webdriver.py", line 312, in execute
    self.error_handler.check_response(response)
  File "C:\Users\admin\AppData\Local\Programs\Python\Python35\lib\site-packages\selenium\webdriver\remote\errorhandler.py", line 237, in check_response
    raise exception_class(message, screen, stacktrace)
selenium.common.exceptions.NoSuchElementException: Message: no such element: Unable to locate element: {"method":"xpath","selector":"//*[@id="productList"]"}
  (Session info: headless chrome=65.0.3325.162)
  (Driver info: chromedriver=2.36.540470 (e522d04694c7ebea4ba8821272dbef4f9b818c91),platform=Windows NT 6.3.9600 x86_64)


(2018-03-20 01:00:30)
===============================================

Exceptions: () traceback : Traceback (most recent call last):
  File "C:/Users/admin/IdeaProjects/py-myweb_crawler/crawler.py", line 292, in out_from_xpath
    return root.find_elements_by_xpath(xpath)
  File "C:\Users\admin\AppData\Local\Programs\Python\Python35\lib\site-packages\selenium\webdriver\remote\webdriver.py", line 401, in find_elements_by_xpath
    return self.find_elements(by=By.XPATH, value=xpath)
  File "C:\Users\admin\AppData\Local\Programs\Python\Python35\lib\site-packages\selenium\webdriver\remote\webdriver.py", line 983, in find_elements
    'value': value})['value'] or []
  File "C:\Users\admin\AppData\Local\Programs\Python\Python35\lib\site-packages\selenium\webdriver\remote\webdriver.py", line 312, in execute
    self.error_handler.check_response(response)
  File "C:\Users\admin\AppData\Local\Programs\Python\Python35\lib\site-packages\selenium\webdriver\remote\errorhandler.py", line 237, in check_response
    raise exception_class(message, screen, stacktrace)
selenium.common.exceptions.UnexpectedAlertPresentException: Alert Text: None
Message: unexpected alert open: {Alert text : 데이터 처리에 실패했습니다. 다시 시도해 주세요.}
  (Session info: headless chrome=65.0.3325.162)
  (Driver info: chromedriver=2.36.540470 (e522d04694c7ebea4ba8821272dbef4f9b818c91),platform=Windows NT 6.3.9600 x86_64)


During handling of the above exception, another exception occurred:

Traceback (most recent call last):
  File "C:/Users/admin/IdeaProjects/py-myweb_crawler/crawler.py", line 255, in find_category_info
    loaded_categories = ParserImpl.out_from_xpath(driver, categories)
  File "C:/Users/admin/IdeaProjects/py-myweb_crawler/crawler.py", line 297, in out_from_xpath
    raise NoSuchElementException
selenium.common.exceptions.NoSuchElementException: Message: None


During handling of the above exception, another exception occurred:

Traceback (most recent call last):
  File "C:/Users/admin/IdeaProjects/py-myweb_crawler/crawler.py", line 203, in parse_to_list
    root, self.parser_unit.categories, self.parser_unit.category_core
  File "C:/Users/admin/IdeaProjects/py-myweb_crawler/crawler.py", line 279, in find_category_info
    raise NoSuchElementException
selenium.common.exceptions.NoSuchElementException: Message: None


(2018-03-20 01:01:40)
===============================================

Exceptions: ('no such element: Unable to locate element: {"method":"xpath","selector":"//*[@id="productList"]"}\n  (Session info: headless chrome=65.0.3325.162)\n  (Driver info: chromedriver=2.36.540470 (e522d04694c7ebea4ba8821272dbef4f9b818c91),platform=Windows NT 6.3.9600 x86_64)', None, None) traceback : Traceback (most recent call last):
  File "C:/Users/admin/IdeaProjects/py-myweb_crawler/crawler.py", line 185, in parse_to_list
    section = driver.find_element_by_xpath(self.parser_unit.section)
  File "C:\Users\admin\AppData\Local\Programs\Python\Python35\lib\site-packages\selenium\webdriver\remote\webdriver.py", line 385, in find_element_by_xpath
    return self.find_element(by=By.XPATH, value=xpath)
  File "C:\Users\admin\AppData\Local\Programs\Python\Python35\lib\site-packages\selenium\webdriver\remote\webdriver.py", line 955, in find_element
    'value': value})['value']
  File "C:\Users\admin\AppData\Local\Programs\Python\Python35\lib\site-packages\selenium\webdriver\remote\webdriver.py", line 312, in execute
    self.error_handler.check_response(response)
  File "C:\Users\admin\AppData\Local\Programs\Python\Python35\lib\site-packages\selenium\webdriver\remote\errorhandler.py", line 237, in check_response
    raise exception_class(message, screen, stacktrace)
selenium.common.exceptions.NoSuchElementException: Message: no such element: Unable to locate element: {"method":"xpath","selector":"//*[@id="productList"]"}
  (Session info: headless chrome=65.0.3325.162)
  (Driver info: chromedriver=2.36.540470 (e522d04694c7ebea4ba8821272dbef4f9b818c91),platform=Windows NT 6.3.9600 x86_64)


(2018-03-20 01:01:42)
===============================================

Exceptions: () traceback : Traceback (most recent call last):
  File "C:/Users/admin/IdeaProjects/py-myweb_crawler/crawler.py", line 292, in out_from_xpath
    return root.find_elements_by_xpath(xpath)
  File "C:\Users\admin\AppData\Local\Programs\Python\Python35\lib\site-packages\selenium\webdriver\remote\webdriver.py", line 401, in find_elements_by_xpath
    return self.find_elements(by=By.XPATH, value=xpath)
  File "C:\Users\admin\AppData\Local\Programs\Python\Python35\lib\site-packages\selenium\webdriver\remote\webdriver.py", line 983, in find_elements
    'value': value})['value'] or []
  File "C:\Users\admin\AppData\Local\Programs\Python\Python35\lib\site-packages\selenium\webdriver\remote\webdriver.py", line 312, in execute
    self.error_handler.check_response(response)
  File "C:\Users\admin\AppData\Local\Programs\Python\Python35\lib\site-packages\selenium\webdriver\remote\errorhandler.py", line 237, in check_response
    raise exception_class(message, screen, stacktrace)
selenium.common.exceptions.UnexpectedAlertPresentException: Alert Text: None
Message: unexpected alert open: {Alert text : 서비스 접속이 원할하지 않습니다.
잠시 후에 다시 방문하여 주시기 바랍니다.}
  (Session info: headless chrome=65.0.3325.162)
  (Driver info: chromedriver=2.36.540470 (e522d04694c7ebea4ba8821272dbef4f9b818c91),platform=Windows NT 6.3.9600 x86_64)


During handling of the above exception, another exception occurred:

Traceback (most recent call last):
  File "C:/Users/admin/IdeaProjects/py-myweb_crawler/crawler.py", line 255, in find_category_info
    loaded_categories = ParserImpl.out_from_xpath(driver, categories)
  File "C:/Users/admin/IdeaProjects/py-myweb_crawler/crawler.py", line 297, in out_from_xpath
    raise NoSuchElementException
selenium.common.exceptions.NoSuchElementException: Message: None


During handling of the above exception, another exception occurred:

Traceback (most recent call last):
  File "C:/Users/admin/IdeaProjects/py-myweb_crawler/crawler.py", line 203, in parse_to_list
    root, self.parser_unit.categories, self.parser_unit.category_core
  File "C:/Users/admin/IdeaProjects/py-myweb_crawler/crawler.py", line 279, in find_category_info
    raise NoSuchElementException
selenium.common.exceptions.NoSuchElementException: Message: None


(2018-03-20 01:05:26)
===============================================

Exceptions: ('no such element: Unable to locate element: {"method":"xpath","selector":"//*[@id="productList"]"}\n  (Session info: headless chrome=65.0.3325.162)\n  (Driver info: chromedriver=2.36.540470 (e522d04694c7ebea4ba8821272dbef4f9b818c91),platform=Windows NT 6.3.9600 x86_64)', None, None) traceback : Traceback (most recent call last):
  File "C:/Users/admin/IdeaProjects/py-myweb_crawler/crawler.py", line 185, in parse_to_list
    section = Repeater.repeat_function(driver.find_element_by_xpath,{self.parser_unit.section},StaleElementReferenceException,6)
  File "C:\Users\admin\IdeaProjects\py-myweb_crawler\repeater.py", line 24, in repeat_function
    return func(*params)
  File "C:\Users\admin\AppData\Local\Programs\Python\Python35\lib\site-packages\selenium\webdriver\remote\webdriver.py", line 385, in find_element_by_xpath
    return self.find_element(by=By.XPATH, value=xpath)
  File "C:\Users\admin\AppData\Local\Programs\Python\Python35\lib\site-packages\selenium\webdriver\remote\webdriver.py", line 955, in find_element
    'value': value})['value']
  File "C:\Users\admin\AppData\Local\Programs\Python\Python35\lib\site-packages\selenium\webdriver\remote\webdriver.py", line 312, in execute
    self.error_handler.check_response(response)
  File "C:\Users\admin\AppData\Local\Programs\Python\Python35\lib\site-packages\selenium\webdriver\remote\errorhandler.py", line 237, in check_response
    raise exception_class(message, screen, stacktrace)
selenium.common.exceptions.NoSuchElementException: Message: no such element: Unable to locate element: {"method":"xpath","selector":"//*[@id="productList"]"}
  (Session info: headless chrome=65.0.3325.162)
  (Driver info: chromedriver=2.36.540470 (e522d04694c7ebea4ba8821272dbef4f9b818c91),platform=Windows NT 6.3.9600 x86_64)


(2018-03-20 01:05:28)
===============================================

Exceptions: () traceback : Traceback (most recent call last):
  File "C:/Users/admin/IdeaProjects/py-myweb_crawler/crawler.py", line 292, in out_from_xpath
    return root.find_elements_by_xpath(xpath)
  File "C:\Users\admin\AppData\Local\Programs\Python\Python35\lib\site-packages\selenium\webdriver\remote\webdriver.py", line 401, in find_elements_by_xpath
    return self.find_elements(by=By.XPATH, value=xpath)
  File "C:\Users\admin\AppData\Local\Programs\Python\Python35\lib\site-packages\selenium\webdriver\remote\webdriver.py", line 983, in find_elements
    'value': value})['value'] or []
  File "C:\Users\admin\AppData\Local\Programs\Python\Python35\lib\site-packages\selenium\webdriver\remote\webdriver.py", line 312, in execute
    self.error_handler.check_response(response)
  File "C:\Users\admin\AppData\Local\Programs\Python\Python35\lib\site-packages\selenium\webdriver\remote\errorhandler.py", line 237, in check_response
    raise exception_class(message, screen, stacktrace)
selenium.common.exceptions.UnexpectedAlertPresentException: Alert Text: None
Message: unexpected alert open: {Alert text : 데이터 처리에 실패했습니다. 다시 시도해 주세요.}
  (Session info: headless chrome=65.0.3325.162)
  (Driver info: chromedriver=2.36.540470 (e522d04694c7ebea4ba8821272dbef4f9b818c91),platform=Windows NT 6.3.9600 x86_64)


During handling of the above exception, another exception occurred:

Traceback (most recent call last):
  File "C:/Users/admin/IdeaProjects/py-myweb_crawler/crawler.py", line 255, in find_category_info
    loaded_categories = ParserImpl.out_from_xpath(driver, categories)
  File "C:/Users/admin/IdeaProjects/py-myweb_crawler/crawler.py", line 297, in out_from_xpath
    raise NoSuchElementException
selenium.common.exceptions.NoSuchElementException: Message: None


During handling of the above exception, another exception occurred:

Traceback (most recent call last):
  File "C:/Users/admin/IdeaProjects/py-myweb_crawler/crawler.py", line 203, in parse_to_list
    root, self.parser_unit.categories, self.parser_unit.category_core
  File "C:/Users/admin/IdeaProjects/py-myweb_crawler/crawler.py", line 279, in find_category_info
    raise NoSuchElementException
selenium.common.exceptions.NoSuchElementException: Message: None


(2018-03-20 01:06:27)
===============================================

Exceptions: ('no such element: Unable to locate element: {"method":"xpath","selector":"//*[@id="productList"]"}\n  (Session info: headless chrome=65.0.3325.162)\n  (Driver info: chromedriver=2.36.540470 (e522d04694c7ebea4ba8821272dbef4f9b818c91),platform=Windows NT 6.3.9600 x86_64)', None, None) traceback : Traceback (most recent call last):
  File "C:/Users/admin/IdeaProjects/py-myweb_crawler/crawler.py", line 185, in parse_to_list
    section = Repeater.repeat_function(driver.find_element_by_xpath,{self.parser_unit.section},StaleElementReferenceException,6)
  File "C:\Users\admin\IdeaProjects\py-myweb_crawler\repeater.py", line 24, in repeat_function
    return func(*params)
  File "C:\Users\admin\AppData\Local\Programs\Python\Python35\lib\site-packages\selenium\webdriver\remote\webdriver.py", line 385, in find_element_by_xpath
    return self.find_element(by=By.XPATH, value=xpath)
  File "C:\Users\admin\AppData\Local\Programs\Python\Python35\lib\site-packages\selenium\webdriver\remote\webdriver.py", line 955, in find_element
    'value': value})['value']
  File "C:\Users\admin\AppData\Local\Programs\Python\Python35\lib\site-packages\selenium\webdriver\remote\webdriver.py", line 312, in execute
    self.error_handler.check_response(response)
  File "C:\Users\admin\AppData\Local\Programs\Python\Python35\lib\site-packages\selenium\webdriver\remote\errorhandler.py", line 237, in check_response
    raise exception_class(message, screen, stacktrace)
selenium.common.exceptions.NoSuchElementException: Message: no such element: Unable to locate element: {"method":"xpath","selector":"//*[@id="productList"]"}
  (Session info: headless chrome=65.0.3325.162)
  (Driver info: chromedriver=2.36.540470 (e522d04694c7ebea4ba8821272dbef4f9b818c91),platform=Windows NT 6.3.9600 x86_64)


(2018-03-20 01:06:28)
===============================================

Exceptions: ('no such element: Unable to locate element: {"method":"xpath","selector":"//*[@id="_resultDeals"]"}\n  (Session info: headless chrome=65.0.3325.162)\n  (Driver info: chromedriver=2.36.540470 (e522d04694c7ebea4ba8821272dbef4f9b818c91),platform=Windows NT 6.3.9600 x86_64)', None, None) traceback : Traceback (most recent call last):
  File "C:/Users/admin/IdeaProjects/py-myweb_crawler/crawler.py", line 185, in parse_to_list
    section = Repeater.repeat_function(driver.find_element_by_xpath,{self.parser_unit.section},StaleElementReferenceException,6)
  File "C:\Users\admin\IdeaProjects\py-myweb_crawler\repeater.py", line 24, in repeat_function
    return func(*params)
  File "C:\Users\admin\AppData\Local\Programs\Python\Python35\lib\site-packages\selenium\webdriver\remote\webdriver.py", line 385, in find_element_by_xpath
    return self.find_element(by=By.XPATH, value=xpath)
  File "C:\Users\admin\AppData\Local\Programs\Python\Python35\lib\site-packages\selenium\webdriver\remote\webdriver.py", line 955, in find_element
    'value': value})['value']
  File "C:\Users\admin\AppData\Local\Programs\Python\Python35\lib\site-packages\selenium\webdriver\remote\webdriver.py", line 312, in execute
    self.error_handler.check_response(response)
  File "C:\Users\admin\AppData\Local\Programs\Python\Python35\lib\site-packages\selenium\webdriver\remote\errorhandler.py", line 237, in check_response
    raise exception_class(message, screen, stacktrace)
selenium.common.exceptions.NoSuchElementException: Message: no such element: Unable to locate element: {"method":"xpath","selector":"//*[@id="_resultDeals"]"}
  (Session info: headless chrome=65.0.3325.162)
  (Driver info: chromedriver=2.36.540470 (e522d04694c7ebea4ba8821272dbef4f9b818c91),platform=Windows NT 6.3.9600 x86_64)


(2018-03-20 01:10:41)
===============================================

